Workbook

Sheet 배송정보
A1: 수취인번호 | B1: 받는사람 이름 | C1: 연락처 | D1: 우편번호 | E1: 주소 | F1: 개인통관고유부호(PCCC) | G1: 배송메시지 | H1: 상품명 | I1: 색상 | J1: 사이즈 | K1: 수량 | L1: SKU | M1: 판매 플랫폼 | N1: 판매업체 상호 | O1: 제품 URL | P1: 주문번호 | Q1: 주문 완료 일시 | R1: 상품별 주문번호 | S1: 일회용 인증번호 | T1: 무게(kg)
A2: 1 | B2: 홍길동 | C2: 010-1234-5678 | D2: 06236 | E2: 서울특별시 강남구 테헤란로 123 | F2: P123456789012 | G2: 부재시 문앞에 놔주세요 | H2: [AS UGG] Adrian (AS2102) | I2: Black | J2: 35 | K2: 2 | L2: AS-AS2102-BLACK-35 | M2: 스마트스토어 | N2: 호주나라몰 | O2: https://smartstore.naver.com/example/products/1234567890 | P2: 2026093012345678 | Q2: 2026-09-30 14:25 | R2: 2026093087654321 | T2: =IF(H2="","",IFERROR(IF(K2="",1,K2)*IFERROR(INDEX('AS UGG'!$H:$H,MATCH(TRIM(L2),'AS UGG'!$G:$G,0)),IFERROR(INDEX(Ozlana!$H:$H,MATCH(TRIM(L2),Ozlana!$G:$G,0)),IFERROR(INDEX(OZWEAR!$H:$H,MATCH(TRIM(L2),OZWEAR!$G:$G,0)),IFERROR(INDEX('AS UGG'!$H:$H,MATCH(UPPER(TRIM(H2))&"|"&UPPER(TRIM(I2))&"|"&UPPER(TRIM(J2)),'AS UGG'!$Z:$Z,0)),IFERROR(INDEX(Ozlana!$H:$H,MATCH(UPPER(TRIM(H2))&"|"&UPPER(TRIM(I2))&"|"&UPPER(TRIM(J2)),Ozlana!$Z:$Z,0)),INDEX(OZWEAR!$H:$H,MATCH(UPPER(TRIM(H2))&"|"&UPPER(TRIM(I2))&"|"&UPPER(TRIM(J2)),OZWEAR!$Z:$Z,0))))))),"상품명/색상/사이즈 확인"))
A3: 1 | B3: 홍길동 | C3: 010-1234-5678 | D3: 06236 | E3: 서울특별시 강남구 테헤란로 123 | F3: P123456789012 | G3: 부재시 문앞에 놔주세요 | H3: Ozlana OZ8001 Logo Fur-Trimmed Reversible Shearling Jacket | I3: CAMEL | J3: S | K3: 1 | L3: OZ8001-CAMEL-S | M3: 스마트스토어 | N3: 호주나라몰 | O3: https://smartstore.naver.com/example/products/9876543210 | P3: 2026093012345678 | Q3: 2026-09-30 14:25 | R3: 2026093087654322 | T3: =IF(H3="","",IFERROR(IF(K3="",1,K3)*IFERROR(INDEX('AS UGG'!$H:$H,MATCH(TRIM(L3),'AS UGG'!$G:$G,0)),IFERROR(INDEX(Ozlana!$H:$H,MATCH(TRIM(L3),Ozlana!$G:$G,0)),IFERROR(INDEX(OZWEAR!$H:$H,MATCH(TRIM(L3),OZWEAR!$G:$G,0)),IFERROR(INDEX('AS UGG'!$H:$H,MATCH(UPPER(TRIM(H3))&"|"&UPPER(TRIM(I3))&"|"&UPPER(TRIM(J3)),'AS UGG'!$Z:$Z,0)),IFERROR(INDEX(Ozlana!$H:$H,MATCH(UPPER(TRIM(H3))&"|"&UPPER(TRIM(I3))&"|"&UPPER(TRIM(J3)),Ozlana!$Z:$Z,0)),INDEX(OZWEAR!$H:$H,MATCH(UPPER(TRIM(H3))&"|"&UPPER(TRIM(I3))&"|"&UPPER(TRIM(J3)),OZWEAR!$Z:$Z,0))))))),"상품명/색상/사이즈 확인"))
A4: ※ 위 1~2번 줄은 작성 예시입니다 (홍길동 님이 상품 2개를 받는 경우). 실제 주문은 3번째 줄부터 이어서 입력해주세요. ※ 같은 사람이 여러 상품을 받으면, 받는사람 정보(이름~배송메시지)를 그대로 복사하고 상품명/색상/사이즈/수량/SKU만 바꿔서 줄을 추가해주세요. ※ 상품명·색상·사이즈·가격·SKU는 뒤의 AS UGG / Ozlana / OZWEAR 시트에서 확인 후 그대로 옮겨 적어주세요. ※ [통관 필수] 판매 플랫폼·판매업체 상호·제품 URL·주문번호·주문 완료 일시·상품별 주문번호는 관세청 전자상거래 통관 정보입니다. 빠지면 통관이 되지 않으니 상품 줄마다 꼭 적어주세요. ※ 받는사람 이름·연락처·우편번호는 구매자가 관세청에 등록한 개인통관고유부호 정보와 같아야 합니다. 2026년 8월 28일 이후 통관부호를 새로 발급/변경한 구매자는 일회용 인증번호도 받아 적어주세요. ※ 무게(kg) 칸은 자동 계산되니 입력하지 마세요.
T5: =IF(H5="","",IFERROR(IF(K5="",1,K5)*IFERROR(INDEX('AS UGG'!$H:$H,MATCH(TRIM(L5),'AS UGG'!$G:$G,0)),IFERROR(INDEX(Ozlana!$H:$H,MATCH(TRIM(L5),Ozlana!$G:$G,0)),IFERROR(INDEX(OZWEAR!$H:$H,MATCH(TRIM(L5),OZWEAR!$G:$G,0)),IFERROR(INDEX('AS UGG'!$H:$H,MATCH(UPPER(TRIM(H5))&"|"&UPPER(TRIM(I5))&"|"&UPPER(TRIM(J5)),'AS UGG'!$Z:$Z,0)),IFERROR(INDEX(Ozlana!$H:$H,MATCH(UPPER(TRIM(H5))&"|"&UPPER(TRIM(I5))&"|"&UPPER(TRIM(J5)),Ozlana!$Z:$Z,0)),INDEX(OZWEAR!$H:$H,MATCH(UPPER(TRIM(H5))&"|"&UPPER(TRIM(I5))&"|"&UPPER(TRIM(J5)),OZWEAR!$Z:$Z,0))))))),"상품명/색상/사이즈 확인"))
T6: =IF(H6="","",IFERROR(IF(K6="",1,K6)*IFERROR(INDEX('AS UGG'!$H:$H,MATCH(TRIM(L6),'AS UGG'!$G:$G,0)),IFERROR(INDEX(Ozlana!$H:$H,MATCH(TRIM(L6),Ozlana!$G:$G,0)),IFERROR(INDEX(OZWEAR!$H:$H,MATCH(TRIM(L6),OZWEAR!$G:$G,0)),IFERROR(INDEX('AS UGG'!$H:$H,MATCH(UPPER(TRIM(H6))&"|"&UPPER(TRIM(I6))&"|"&UPPER(TRIM(J6)),'AS UGG'!$Z:$Z,0)),IFERROR(INDEX(Ozlana!$H:$H,MATCH(UPPER(TRIM(H6))&"|"&UPPER(TRIM(I6))&"|"&UPPER(TRIM(J6)),Ozlana!$Z:$Z,0)),INDEX(OZWEAR!$H:$H,MATCH(UPPER(TRIM(H6))&"|"&UPPER(TRIM(I6))&"|"&UPPER(TRIM(J6)),OZWEAR!$Z:$Z,0))))))),"상품명/색상/사이즈 확인"))
T7: =IF(H7="","",IFERROR(IF(K7="",1,K7)*IFERROR(INDEX('AS UGG'!$H:$H,MATCH(TRIM(L7),'AS UGG'!$G:$G,0)),IFERROR(INDEX(Ozlana!$H:$H,MATCH(TRIM(L7),Ozlana!$G:$G,0)),IFERROR(INDEX(OZWEAR!$H:$H,MATCH(TRIM(L7),OZWEAR!$G:$G,0)),IFERROR(INDEX('AS UGG'!$H:$H,MATCH(UPPER(TRIM(H7))&"|"&UPPER(TRIM(I7))&"|"&UPPER(TRIM(J7)),'AS UGG'!$Z:$Z,0)),IFERROR(INDEX(Ozlana!$H:$H,MATCH(UPPER(TRIM(H7))&"|"&UPPER(TRIM(I7))&"|"&UPPER(TRIM(J7)),Ozlana!$Z:$Z,0)),INDEX(OZWEAR!$H:$H,MATCH(UPPER(TRIM(H7))&"|"&UPPER(TRIM(I7))&"|"&UPPER(TRIM(J7)),OZWEAR!$Z:$Z,0))))))),"상품명/색상/사이즈 확인"))
T8: =IF(H8="","",IFERROR(IF(K8="",1,K8)*IFERROR(INDEX('AS UGG'!$H:$H,MATCH(TRIM(L8),'AS UGG'!$G:$G,0)),IFERROR(INDEX(Ozlana!$H:$H,MATCH(TRIM(L8),Ozlana!$G:$G,0)),IFERROR(INDEX(OZWEAR!$H:$H,MATCH(TRIM(L8),OZWEAR!$G:$G,0)),IFERROR(INDEX('AS UGG'!$H:$H,MATCH(UPPER(TRIM(H8))&"|"&UPPER(TRIM(I8))&"|"&UPPER(TRIM(J8)),'AS UGG'!$Z:$Z,0)),IFERROR(INDEX(Ozlana!$H:$H,MATCH(UPPER(TRIM(H8))&"|"&UPPER(TRIM(I8))&"|"&UPPER(TRIM(J8)),Ozlana!$Z:$Z,0)),INDEX(OZWEAR!$H:$H,MATCH(UPPER(TRIM(H8))&"|"&UPPER(TRIM(I8))&"|"&UPPER(TRIM(J8)),OZWEAR!$Z:$Z,0))))))),"상품명/색상/사이즈 확인"))
T9: =IF(H9="","",IFERROR(IF(K9="",1,K9)*IFERROR(INDEX('AS UGG'!$H:$H,MATCH(TRIM(L9),'AS UGG'!$G:$G,0)),IFERROR(INDEX(Ozlana!$H:$H,MATCH(TRIM(L9),Ozlana!$G:$G,0)),IFERROR(INDEX(OZWEAR!$H:$H,MATCH(TRIM(L9),OZWEAR!$G:$G,0)),IFERROR(INDEX('AS UGG'!$H:$H,MATCH(UPPER(TRIM(H9))&"|"&UPPER(TRIM(I9))&"|"&UPPER(TRIM(J9)),'AS UGG'!$Z:$Z,0)),IFERROR(INDEX(Ozlana!$H:$H,MATCH(UPPER(TRIM(H9))&"|"&UPPER(TRIM(I9))&"|"&UPPER(TRIM(J9)),Ozlana!$Z:$Z,0)),INDEX(OZWEAR!$H:$H,MATCH(UPPER(TRIM(H9))&"|"&UPPER(TRIM(I9))&"|"&UPPER(TRIM(J9)),OZWEAR!$Z:$Z,0))))))),"상품명/색상/사이즈 확인"))
T10: =IF(H10="","",IFERROR(IF(K10="",1,K10)*IFERROR(INDEX('AS UGG'!$H:$H,MATCH(TRIM(L10),'AS UGG'!$G:$G,0)),IFERROR(INDEX(Ozlana!$H:$H,MATCH(TRIM(L10),Ozlana!$G:$G,0)),IFERROR(INDEX(OZWEAR!$H:$H,MATCH(TRIM(L10),OZWEAR!$G:$G,0)),IFERROR(INDEX('AS UGG'!$H:$H,MATCH(UPPER(TRIM(H10))&"|"&UPPER(TRIM(I10))&"|"&UPPER(TRIM(J10)),'AS UGG'!$Z:$Z,0)),IFERROR(INDEX(Ozlana!$H:$H,MATCH(UPPER(TRIM(H10))&"|"&UPPER(TRIM(I10))&"|"&UPPER(TRIM(J10)),Ozlana!$Z:$Z,0)),INDEX(OZWEAR!$H:$H,MATCH(UPPER(TRIM(H10))&"|"&UPPER(TRIM(I10))&"|"&UPPER(TRIM(J10)),OZWEAR!$Z:$Z,0))))))),"상품명/색상/사이즈 확인"))
T11: =IF(H11="","",IFERROR(IF(K11="",1,K11)*IFERROR(INDEX('AS UGG'!$H:$H,MATCH(TRIM(L11),'AS UGG'!$G:$G,0)),IFERROR(INDEX(Ozlana!$H:$H,MATCH(TRIM(L11),Ozlana!$G:$G,0)),IFERROR(INDEX(OZWEAR!$H:$H,MATCH(TRIM(L11),OZWEAR!$G:$G,0)),IFERROR(INDEX('AS UGG'!$H:$H,MATCH(UPPER(TRIM(H11))&"|"&UPPER(TRIM(I11))&"|"&UPPER(TRIM(J11)),'AS UGG'!$Z:$Z,0)),IFERROR(INDEX(Ozlana!$H:$H,MATCH(UPPER(TRIM(H11))&"|"&UPPER(TRIM(I11))&"|"&UPPER(TRIM(J11)),Ozlana!$Z:$Z,0)),INDEX(OZWEAR!$H:$H,MATCH(UPPER(TRIM(H11))&"|"&UPPER(TRIM(I11))&"|"&UPPER(TRIM(J11)),OZWEAR!$Z:$Z,0))))))),"상품명/색상/사이즈 확인"))
T12: =IF(H12="","",IFERROR(IF(K12="",1,K12)*IFERROR(INDEX('AS UGG'!$H:$H,MATCH(TRIM(L12),'AS UGG'!$G:$G,0)),IFERROR(INDEX(Ozlana!$H:$H,MATCH(TRIM(L12),Ozlana!$G:$G,0)),IFERROR(INDEX(OZWEAR!$H:$H,MATCH(TRIM(L12),OZWEAR!$G:$G,0)),IFERROR(INDEX('AS UGG'!$H:$H,MATCH(UPPER(TRIM(H12))&"|"&UPPER(TRIM(I12))&"|"&UPPER(TRIM(J12)),'AS UGG'!$Z:$Z,0)),IFERROR(INDEX(Ozlana!$H:$H,MATCH(UPPER(TRIM(H12))&"|"&UPPER(TRIM(I12))&"|"&UPPER(TRIM(J12)),Ozlana!$Z:$Z,0)),INDEX(OZWEAR!$H:$H,MATCH(UPPER(TRIM(H12))&"|"&UPPER(TRIM(I12))&"|"&UPPER(TRIM(J12)),OZWEAR!$Z:$Z,0))))))),"상품명/색상/사이즈 확인"))
T13: =IF(H13="","",IFERROR(IF(K13="",1,K13)*IFERROR(INDEX('AS UGG'!$H:$H,MATCH(TRIM(L13),'AS UGG'!$G:$G,0)),IFERROR(INDEX(Ozlana!$H:$H,MATCH(TRIM(L13),Ozlana!$G:$G,0)),IFERROR(INDEX(OZWEAR!$H:$H,MATCH(TRIM(L13),OZWEAR!$G:$G,0)),IFERROR(INDEX('AS UGG'!$H:$H,MATCH(UPPER(TRIM(H13))&"|"&UPPER(TRIM(I13))&"|"&UPPER(TRIM(J13)),'AS UGG'!$Z:$Z,0)),IFERROR(INDEX(Ozlana!$H:$H,MATCH(UPPER(TRIM(H13))&"|"&UPPER(TRIM(I13))&"|"&UPPER(TRIM(J13)),Ozlana!$Z:$Z,0)),INDEX(OZWEAR!$H:$H,MATCH(UPPER(TRIM(H13))&"|"&UPPER(TRIM(I13))&"|"&UPPER(TRIM(J13)),OZWEAR!$Z:$Z,0))))))),"상품명/색상/사이즈 확인"))
T14: =IF(H14="","",IFERROR(IF(K14="",1,K14)*IFERROR(INDEX('AS UGG'!$H:$H,MATCH(TRIM(L14),'AS UGG'!$G:$G,0)),IFERROR(INDEX(Ozlana!$H:$H,MATCH(TRIM(L14),Ozlana!$G:$G,0)),IFERROR(INDEX(OZWEAR!$H:$H,MATCH(TRIM(L14),OZWEAR!$G:$G,0)),IFERROR(INDEX('AS UGG'!$H:$H,MATCH(UPPER(TRIM(H14))&"|"&UPPER(TRIM(I14))&"|"&UPPER(TRIM(J14)),'AS UGG'!$Z:$Z,0)),IFERROR(INDEX(Ozlana!$H:$H,MATCH(UPPER(TRIM(H14))&"|"&UPPER(TRIM(I14))&"|"&UPPER(TRIM(J14)),Ozlana!$Z:$Z,0)),INDEX(OZWEAR!$H:$H,MATCH(UPPER(TRIM(H14))&"|"&UPPER(TRIM(I14))&"|"&UPPER(TRIM(J14)),OZWEAR!$Z:$Z,0))))))),"상품명/색상/사이즈 확인"))
T15: =IF(H15="","",IFERROR(IF(K15="",1,K15)*IFERROR(INDEX('AS UGG'!$H:$H,MATCH(TRIM(L15),'AS UGG'!$G:$G,0)),IFERROR(INDEX(Ozlana!$H:$H,MATCH(TRIM(L15),Ozlana!$G:$G,0)),IFERROR(INDEX(OZWEAR!$H:$H,MATCH(TRIM(L15),OZWEAR!$G:$G,0)),IFERROR(INDEX('AS UGG'!$H:$H,MATCH(UPPER(TRIM(H15))&"|"&UPPER(TRIM(I15))&"|"&UPPER(TRIM(J15)),'AS UGG'!$Z:$Z,0)),IFERROR(INDEX(Ozlana!$H:$H,MATCH(UPPER(TRIM(H15))&"|"&UPPER(TRIM(I15))&"|"&UPPER(TRIM(J15)),Ozlana!$Z:$Z,0)),INDEX(OZWEAR!$H:$H,MATCH(UPPER(TRIM(H15))&"|"&UPPER(TRIM(I15))&"|"&UPPER(TRIM(J15)),OZWEAR!$Z:$Z,0))))))),"상품명/색상/사이즈 확인"))
T16: =IF(H16="","",IFERROR(IF(K16="",1,K16)*IFERROR(INDEX('AS UGG'!$H:$H,MATCH(TRIM(L16),'AS UGG'!$G:$G,0)),IFERROR(INDEX(Ozlana!$H:$H,MATCH(TRIM(L16),Ozlana!$G:$G,0)),IFERROR(INDEX(OZWEAR!$H:$H,MATCH(TRIM(L16),OZWEAR!$G:$G,0)),IFERROR(INDEX('AS UGG'!$H:$H,MATCH(UPPER(TRIM(H16))&"|"&UPPER(TRIM(I16))&"|"&UPPER(TRIM(J16)),'AS UGG'!$Z:$Z,0)),IFERROR(INDEX(Ozlana!$H:$H,MATCH(UPPER(TRIM(H16))&"|"&UPPER(TRIM(I16))&"|"&UPPER(TRIM(J16)),Ozlana!$Z:$Z,0)),INDEX(OZWEAR!$H:$H,MATCH(UPPER(TRIM(H16))&"|"&UPPER(TRIM(I16))&"|"&UPPER(TRIM(J16)),OZWEAR!$Z:$Z,0))))))),"상품명/색상/사이즈 확인"))
... T1000: =IF(H1000="","",IFERROR(IF(K1000="",1,K1000)*IFERROR(INDEX('AS UGG'!$H:$H,MATCH(TRIM(L1000),'AS UGG'!$G:$G,0)),IFERROR(INDEX(Ozlana!$H:$H,MATCH(TRIM(L1000),Ozlana!$G:$G,0)),IFERROR(INDEX(OZWEAR!$H:$H,MATCH(TRIM(L1000),OZWEAR!$G:$G,0)),IFERROR(INDEX('AS UGG'!$H:$H,MATCH(UPPER(TRIM(H1000))&"|"&UPPER(TRIM(I1000))&"|"&UPPER(TRIM(J1000)),'AS UGG'!$Z:$Z,0)),IFERROR(INDEX(Ozlana!$H:$H,MATCH(UPPER(TRIM(H1000))&"|"&UPPER(TRIM(I1000))&"|"&UPPER(TRIM(J1000)),Ozlana!$Z:$Z,0)),INDEX(OZWEAR!$H:$H,MATCH(UPPER(TRIM(H1000))&"|"&UPPER(TRIM(I1000))&"|"&UPPER(TRIM(J1000)),OZWEAR!$Z:$Z,0))))))),"상품명/색상/사이즈 확인"))

Sheet AS UGG
A1: 브랜드 | B1: 상품명 | C1: 색상 | D1: 사이즈 | E1: 가격(AUD) | F1: 재고 | G1: SKU | H1: 무게(kg) | Z1: 조회키
A2: AS UGG | B2: [AS UGG] Adrian (AS2102) | C2: Black | D2: 35 | E2: 52.8 | F2: 6 | G2: AS-AS2102-BLACK-35 | H2: 2 | Z2: =UPPER(TRIM(B2))&"|"&UPPER(TRIM(C2))&"|"&UPPER(TRIM(D2))
A3: AS UGG | B3: [AS UGG] Adrian (AS2102) | C3: Black | D3: 36 | E3: 52.8 | F3: 6 | G3: AS-AS2102-BLACK-36 | H3: 2 | Z3: =UPPER(TRIM(B3))&"|"&UPPER(TRIM(C3))&"|"&UPPER(TRIM(D3))
A4: AS UGG | B4: [AS UGG] Adrian (AS2102) | C4: Black | D4: 37 | E4: 52.8 | F4: 8 | G4: AS-AS2102-BLACK-37 | H4: 2 | Z4: =UPPER(TRIM(B4))&"|"&UPPER(TRIM(C4))&"|"&UPPER(TRIM(D4))
A5: AS UGG | B5: [AS UGG] Adrian (AS2102) | C5: Black | D5: 38 | E5: 52.8 | F5: 0 | G5: AS-AS2102-BLACK-38 | H5: 2 | Z5: =UPPER(TRIM(B5))&"|"&UPPER(TRIM(C5))&"|"&UPPER(TRIM(D5))
A6: AS UGG | B6: [AS UGG] Adrian (AS2102) | C6: Black | D6: 39 | E6: 52.8 | F6: 4 | G6: AS-AS2102-BLACK-39 | H6: 2 | Z6: =UPPER(TRIM(B6))&"|"&UPPER(TRIM(C6))&"|"&UPPER(TRIM(D6))
A7: AS UGG | B7: [AS UGG] Adrian (AS2102) | C7: Black | D7: 40 | E7: 52.8 | F7: 6 | G7: AS-AS2102-BLACK-40 | H7: 2 | Z7: =UPPER(TRIM(B7))&"|"&UPPER(TRIM(C7))&"|"&UPPER(TRIM(D7))
A8: AS UGG | B8: [AS UGG] Adrian (AS2102) | C8: Black | D8: 41 | E8: 52.8 | F8: 3 | G8: AS-AS2102-BLACK-41 | H8: 2 | Z8: =UPPER(TRIM(B8))&"|"&UPPER(TRIM(C8))&"|"&UPPER(TRIM(D8))
A9: AS UGG | B9: [AS UGG] Adrian (AS2102) | C9: Walnut | D9: 35 | E9: 52.8 | F9: 20 | G9: AS-AS2102-WALNUT-35 | H9: 2 | Z9: =UPPER(TRIM(B9))&"|"&UPPER(TRIM(C9))&"|"&UPPER(TRIM(D9))
A10: AS UGG | B10: [AS UGG] Adrian (AS2102) | C10: Walnut | D10: 36 | E10: 52.8 | F10: 21 | G10: AS-AS2102-WALNUT-36 | H10: 2 | Z10: =UPPER(TRIM(B10))&"|"&UPPER(TRIM(C10))&"|"&UPPER(TRIM(D10))
A11: AS UGG | B11: [AS UGG] Adrian (AS2102) | C11: Walnut | D11: 37 | E11: 52.8 | F11: 104 | G11: AS-AS2102-WALNUT-37 | H11: 2 | Z11: =UPPER(TRIM(B11))&"|"&UPPER(TRIM(C11))&"|"&UPPER(TRIM(D11))
A12: AS UGG | B12: [AS UGG] Adrian (AS2102) | C12: Walnut | D12: 38 | E12: 52.8 | F12: 88 | G12: AS-AS2102-WALNUT-38 | H12: 2 | Z12: =UPPER(TRIM(B12))&"|"&UPPER(TRIM(C12))&"|"&UPPER(TRIM(D12))
A13: AS UGG | B13: [AS UGG] Adrian (AS2102) | C13: Walnut | D13: 39 | E13: 52.8 | F13: 79 | G13: AS-AS2102-WALNUT-39 | H13: 2 | Z13: =UPPER(TRIM(B13))&"|"&UPPER(TRIM(C13))&"|"&UPPER(TRIM(D13))
... A60: AS UGG | B60: [AS UGG] Alden (AS2145) | C60: Chestnut | D60: 46 | E60: 54.45 | F60: 0 | G60: AS-AS2145-CHESTNUT-46 | H60: 2 | Z60: =UPPER(TRIM(B60))&"|"&UPPER(TRIM(C60))&"|"&UPPER(TRIM(D60))
A61: AS UGG | B61: [AS UGG] Alpaca Keyrings (ASZ012) | C61: PINK | E61: 6.6 | F61: 43 | G61: AS-ASZ012-PINK | H61: 1 | Z61: =UPPER(TRIM(B61))&"|"&UPPER(TRIM(C61))&"|"&UPPER(TRIM(D61))
A62: AS UGG | B62: [AS UGG] Alpaca Keyrings (ASZ012) | C62: YELLOW | E62: 6.6 | F62: 58 | G62: AS-ASZ012-YELLOW | H62: 1 | Z62: =UPPER(TRIM(B62))&"|"&UPPER(TRIM(C62))&"|"&UPPER(TRIM(D62))
A63: AS UGG | B63: [AS UGG] Alpaca Keyrings (ASZ012) | C63: GREY | E63: 6.6 | F63: 57 | G63: AS-ASZ012-GREY | H63: 1 | Z63: =UPPER(TRIM(B63))&"|"&UPPER(TRIM(C63))&"|"&UPPER(TRIM(D63))
A64: AS UGG | B64: [AS UGG] Ambrelle Bag (ASA054) | C64: Chestnut | E64: 77 | F64: 58 | G64: AS-ASA054-CHESTNUT | H64: 1 | Z64: =UPPER(TRIM(B64))&"|"&UPPER(TRIM(C64))&"|"&UPPER(TRIM(D64))
A65: AS UGG | B65: [AS UGG] Ardell (AS3138) | C65: Pebble Grey | D65: 35 | E65: 71.5 | F65: 5 | G65: AS-AS3138-PEBBLE-GREY-35 | H65: 3 | Z65: =UPPER(TRIM(B65))&"|"&UPPER(TRIM(C65))&"|"&UPPER(TRIM(D65))
A66: AS UGG | B66: [AS UGG] Ardell (AS3138) | C66: Pebble Grey | D66: 36 | E66: 71.5 | F66: 4 | G66: AS-AS3138-PEBBLE-GREY-36 | H66: 3 | Z66: =UPPER(TRIM(B66))&"|"&UPPER(TRIM(C66))&"|"&UPPER(TRIM(D66))
A67: AS UGG | B67: [AS UGG] Ardell (AS3138) | C67: Pebble Grey | D67: 37 | E67: 71.5 | F67: 7 | G67: AS-AS3138-PEBBLE-GREY-37 | H67: 3 | Z67: =UPPER(TRIM(B67))&"|"&UPPER(TRIM(C67))&"|"&UPPER(TRIM(D67))
A68: AS UGG | B68: [AS UGG] Ardell (AS3138) | C68: Pebble Grey | D68: 38 | E68: 71.5 | F68: 11 | G68: AS-AS3138-PEBBLE-GREY-38 | H68: 3 | Z68: =UPPER(TRIM(B68))&"|"&UPPER(TRIM(C68))&"|"&UPPER(TRIM(D68))
A69: AS UGG | B69: [AS UGG] Ardell (AS3138) | C69: Pebble Grey | D69: 39 | E69: 71.5 | F69: 5 | G69: AS-AS3138-PEBBLE-GREY-39 | H69: 3 | Z69: =UPPER(TRIM(B69))&"|"&UPPER(TRIM(C69))&"|"&UPPER(TRIM(D69))
A70: AS UGG | B70: [AS UGG] Ardell (AS3138) | C70: Pebble Grey | D70: 40 | E70: 71.5 | F70: 2 | G70: AS-AS3138-PEBBLE-GREY-40 | H70: 3 | Z70: =UPPER(TRIM(B70))&"|"&UPPER(TRIM(C70))&"|"&UPPER(TRIM(D70))
A71: AS UGG | B71: [AS UGG] Ardell (AS3138) | C71: Pebble Grey | D71: 41 | E71: 71.5 | F71: 2 | G71: AS-AS3138-PEBBLE-GREY-41 | H71: 3 | Z71: =UPPER(TRIM(B71))&"|"&UPPER(TRIM(C71))&"|"&UPPER(TRIM(D71))
A72: AS UGG | B72: [AS UGG] Ardell (AS3138) | C72: Chestnut | D72: 35 | E72: 71.5 | F72: 2 | G72: AS-AS3138-CHESTNUT-35 | H72: 3 | Z72: =UPPER(TRIM(B72))&"|"&UPPER(TRIM(C72))&"|"&UPPER(TRIM(D72))
A73: AS UGG | B73: [AS UGG] Ardell (AS3138) | C73: Chestnut | D73: 36 | E73: 71.5 | F73: 3 | G73: AS-AS3138-CHESTNUT-36 | H73: 3 | Z73: =UPPER(TRIM(B73))&"|"&UPPER(TRIM(C73))&"|"&UPPER(TRIM(D73))
A74: AS UGG | B74: [AS UGG] Ardell (AS3138) | C74: Chestnut | D74: 37 | E74: 71.5 | F74: 8 | G74: AS-AS3138-CHESTNUT-37 | H74: 3 | Z74: =UPPER(TRIM(B74))&"|"&UPPER(TRIM(C74))&"|"&UPPER(TRIM(D74))
A75: AS UGG | B75: [AS UGG] Ardell (AS3138) | C75: Chestnut | D75: 38 | E75: 71.5 | F75: 27 | G75: AS-AS3138-CHESTNUT-38 | H75: 3 | Z75: =UPPER(TRIM(B75))&"|"&UPPER(TRIM(C75))&"|"&UPPER(TRIM(D75))
A76: AS UGG | B76: [AS UGG] Ardell (AS3138) | C76: Chestnut | D76: 39 | E76: 71.5 | F76: 26 | G76: AS-AS3138-CHESTNUT-39 | H76: 3 | Z76: =UPPER(TRIM(B76))&"|"&UPPER(TRIM(C76))&"|"&UPPER(TRIM(D76))
... A98: AS UGG | B98: [AS UGG] Arlen (AS3176) | C98: Chestnut | D98: 40 | E98: 54.45 | F98: 0 | G98: AS-AS3176-CHESTNUT-40 | H98: 3 | Z98: =UPPER(TRIM(B98))&"|"&UPPER(TRIM(C98))&"|"&UPPER(TRIM(D98))
A99: AS UGG | B99: [AS UGG] Arven Scarf (AS8011) | C99: Beige | E99: 47.3 | F99: 430 | G99: AS-AS8011-BEIGE | H99: 1 | Z99: =UPPER(TRIM(B99))&"|"&UPPER(TRIM(C99))&"|"&UPPER(TRIM(D99))
A100: AS UGG | B100: [AS UGG] Arven Scarf (AS8011) | C100: Ivory | E100: 47.3 | F100: 510 | G100: AS-AS8011-IVORY | H100: 1 | Z100: =UPPER(TRIM(B100))&"|"&UPPER(TRIM(C100))&"|"&UPPER(TRIM(D100))
A101: AS UGG | B101: [AS UGG] Arven Scarf (AS8011) | C101: Dark Grey | E101: 47.3 | F101: 506 | G101: AS-AS8011-DARK-GREY | H101: 1 | Z101: =UPPER(TRIM(B101))&"|"&UPPER(TRIM(C101))&"|"&UPPER(TRIM(D101))
A102: AS UGG | B102: [AS UGG] Arven Scarf (AS8011) | C102: Brown | E102: 47.3 | F102: 554 | G102: AS-AS8011-BROWN | H102: 1 | Z102: =UPPER(TRIM(B102))&"|"&UPPER(TRIM(C102))&"|"&UPPER(TRIM(D102))
A103: AS UGG | B103: [AS UGG] Arya (AS3076) | C103: Nappa Black | D103: 35 | E103: 64.9 | F103: 4 | G103: AS-AS3076-NAPPA-BLACK-35 | H103: 3 | Z103: =UPPER(TRIM(B103))&"|"&UPPER(TRIM(C103))&"|"&UPPER(TRIM(D103))
A104: AS UGG | B104: [AS UGG] Arya (AS3076) | C104: Nappa Black | D104: 36 | E104: 64.9 | F104: 1 | G104: AS-AS3076-NAPPA-BLACK-36 | H104: 3 | Z104: =UPPER(TRIM(B104))&"|"&UPPER(TRIM(C104))&"|"&UPPER(TRIM(D104))
A105: AS UGG | B105: [AS UGG] Arya (AS3076) | C105: Nappa Black | D105: 37 | E105: 64.9 | F105: 2 | G105: AS-AS3076-NAPPA-BLACK-37 | H105: 3 | Z105: =UPPER(TRIM(B105))&"|"&UPPER(TRIM(C105))&"|"&UPPER(TRIM(D105))
A106: AS UGG | B106: [AS UGG] Arya (AS3076) | C106: Nappa Black | D106: 38 | E106: 64.9 | F106: 89 | G106: AS-AS3076-NAPPA-BLACK-38 | H106: 3 | Z106: =UPPER(TRIM(B106))&"|"&UPPER(TRIM(C106))&"|"&UPPER(TRIM(D106))
A107: AS UGG | B107: [AS UGG] Arya (AS3076) | C107: Nappa Black | D107: 39 | E107: 64.9 | F107: 82 | G107: AS-AS3076-NAPPA-BLACK-39 | H107: 3 | Z107: =UPPER(TRIM(B107))&"|"&UPPER(TRIM(C107))&"|"&UPPER(TRIM(D107))
...

Sheet Ozlana
A1: 브랜드 | B1: 상품명 | C1: 색상 | D1: 사이즈 | E1: 가격(AUD) | F1: 재고 | G1: SKU | H1: 무게(kg) | I1: OZLANA SIZE CHART (전체 사이즈 범위 - 상품마다 판매 사이즈 범위는 다를 수 있음) | Z1: 조회키
A2: Ozlana | B2: Ozlana OZ8001 Logo Fur-Trimmed Reversible Shearling Jacket | C2: CAMEL | D2: S | E2: 193.6 | F2: 100 | G2: OZ8001-CAMEL-S | H2: 3 | I2: USA | J2: 4 | K2: 5 | L2: 6 | M2: 7 | N2: 8 | O2: 9 | P2: 10 | Q2: 11 | R2: 12 | S2: 13 | Z2: =UPPER(TRIM(B2))&"|"&UPPER(TRIM(C2))&"|"&UPPER(TRIM(D2))
A3: Ozlana | B3: Ozlana OZ8001 Logo Fur-Trimmed Reversible Shearling Jacket | C3: CAMEL | D3: M | E3: 193.6 | F3: 100 | G3: OZ8001-CAMEL-M | H3: 3 | I3: UK | J3: 2 | K3: 3 | L3: 4 | M3: 5 | N3: 6 | O3: 7 | P3: 8 | Q3: 9 | R3: 10 | S3: 11 | Z3: =UPPER(TRIM(B3))&"|"&UPPER(TRIM(C3))&"|"&UPPER(TRIM(D3))
A4: Ozlana | B4: Ozlana OZ8001 Logo Fur-Trimmed Reversible Shearling Jacket | C4: CAMEL | D4: L | E4: 193.6 | F4: 100 | G4: OZ8001-CAMEL-L | H4: 3 | I4: EU | J4: 35 | K4: 36 | L4: 37 | M4: 38 | N4: 39 | O4: 40 | P4: 41 | Q4: 42 | R4: 43 | S4: 44 | Z4: =UPPER(TRIM(B4))&"|"&UPPER(TRIM(C4))&"|"&UPPER(TRIM(D4))
A5: Ozlana | B5: Ozlana OZ8001 Logo Fur-Trimmed Reversible Shearling Jacket | C5: BROWN | D5: S | E5: 193.6 | F5: 100 | G5: OZ8001-BROWN-S | H5: 3 | I5: JAPAN | J5: 225 | K5: 230 | L5: 235 | M5: 240 | N5: 245 | O5: 250 | P5: 255 | Q5: 260 | R5: 265 | S5: 270 | Z5: =UPPER(TRIM(B5))&"|"&UPPER(TRIM(C5))&"|"&UPPER(TRIM(D5))
A6: Ozlana | B6: Ozlana OZ8001 Logo Fur-Trimmed Reversible Shearling Jacket | C6: BROWN | D6: M | E6: 193.6 | F6: 100 | G6: OZ8001-BROWN-M | H6: 3 | Z6: =UPPER(TRIM(B6))&"|"&UPPER(TRIM(C6))&"|"&UPPER(TRIM(D6))
A7: Ozlana | B7: Ozlana OZ8001 Logo Fur-Trimmed Reversible Shearling Jacket | C7: BROWN | D7: L | E7: 193.6 | F7: 100 | G7: OZ8001-BROWN-L | H7: 3 | I7: OZLANA APPAREL SIZE CHART - 실측 사이즈 (단위: cm, 평면 실측 기준 / 1~2cm 오차 가능) | Z7: =UPPER(TRIM(B7))&"|"&UPPER(TRIM(C7))&"|"&UPPER(TRIM(D7))
A8: Ozlana | B8: Ozlana OZ8002 Logo Reversible Shearling Jacket | C8: CHESTNUT | D8: S | E8: 193.6 | F8: 100 | G8: OZ8002-CHESTNUT-S | H8: 3 | I8: STYLE | J8: CHEST | Z8: =UPPER(TRIM(B8))&"|"&UPPER(TRIM(C8))&"|"&UPPER(TRIM(D8))
A9: Ozlana | B9: Ozlana OZ8002 Logo Reversible Shearling Jacket | C9: CHESTNUT | D9: M | E9: 193.6 | F9: 100 | G9: OZ8002-CHESTNUT-M | H9: 3 | K9: M | L9: L | M9: S | N9: M | O9: L | P9: S | Q9: M | R9: L | S9: S | T9: M | U9: L | Z9: =UPPER(TRIM(B9))&"|"&UPPER(TRIM(C9))&"|"&UPPER(TRIM(D9))
A10: Ozlana | B10: Ozlana OZ8002 Logo Reversible Shearling Jacket | C10: CHESTNUT | D10: L | E10: 193.6 | F10: 100 | G10: OZ8002-CHESTNUT-L | H10: 3 | I10: OZ8001 | J10: 126 | K10: 130 | L10: 134 | M10: 56 | N10: 57 | O10: 58 | P10: 54 | Q10: 55 | R10: 56 | S10: 54 | T10: 55 | U10: 56 | Z10: =UPPER(TRIM(B10))&"|"&UPPER(TRIM(C10))&"|"&UPPER(TRIM(D10))
A11: Ozlana | B11: Ozlana OZ8002 Logo Reversible Shearling Jacket | C11: CHOCOLATE | D11: S | E11: 193.6 | F11: 100 | G11: OZ8002-CHOCOLATE-S | H11: 3 | I11: OZ8002 | J11: 110 | K11: 114 | L11: 118 | M11: 59 | N11: 60 | O11: 61 | P11: 53 | Q11: 54 | R11: 55 | S11: 61.5 | T11: 62.5 | U11: 63.5 | Z11: =UPPER(TRIM(B11))&"|"&UPPER(TRIM(C11))&"|"&UPPER(TRIM(D11))
A12: Ozlana | B12: Ozlana OZ8002 Logo Reversible Shearling Jacket | C12: CHOCOLATE | D12: M | E12: 193.6 | F12: 100 | G12: OZ8002-CHOCOLATE-M | H12: 3 | I12: OZ8003 | J12: 112 | K12: 116 | L12: 120 | M12: 52 | N12: 53 | O12: 54 | P12: 53 | Q12: 54 | R12: 55 | S12: 72 | T12: 73 | U12: 74 | Z12: =UPPER(TRIM(B12))&"|"&UPPER(TRIM(C12))&"|"&UPPER(TRIM(D12))
A13: Ozlana | B13: Ozlana OZ8002 Logo Reversible Shearling Jacket | C13: CHOCOLATE | D13: L | E13: 193.6 | F13: 100 | G13: OZ8002-CHOCOLATE-L | H13: 3 | I13: OZ8004 | J13: 94 | K13: 98 | L13: 102 | M13: 35 | N13: 36 | O13: 37 | P13: - | Q13: - | R13: - | S13: 58 | T13: 59 | U13: 60 | Z13: =UPPER(TRIM(B13))&"|"&UPPER(TRIM(C13))&"|"&UPPER(TRIM(D13))
A14: Ozlana | B14: Ozlana OZ8003 Double Logo Reversible Shearling Coat | C14: CHESTNUT | D14: S | E14: 199.65 | F14: 100 | G14: OZ8003-CHESTNUT-S | H14: 3 | I14: OZ8005 | J14: 122 | K14: 126 | L14: 130 | M14: 60 | N14: 61 | O14: 62 | P14: 47 | Q14: 48 | R14: 49 | S14: 60 | T14: 61 | U14: 62 | Z14: =UPPER(TRIM(B14))&"|"&UPPER(TRIM(C14))&"|"&UPPER(TRIM(D14))
A15: Ozlana | B15: Ozlana OZ8003 Double Logo Reversible Shearling Coat | C15: CHESTNUT | D15: M | E15: 199.65 | F15: 100 | G15: OZ8003-CHESTNUT-M | H15: 3 | I15: OZ8006 | J15: 116 | K15: 120 | L15: 124 | M15: 51 | N15: 52 | O15: 53 | P15: 52 | Q15: 53 | R15: 54 | S15: 73 | T15: 74 | U15: 75 | Z15: =UPPER(TRIM(B15))&"|"&UPPER(TRIM(C15))&"|"&UPPER(TRIM(D15))
A16: Ozlana | B16: Ozlana OZ8003 Double Logo Reversible Shearling Coat | C16: CHESTNUT | D16: L | E16: 199.65 | F16: 100 | G16: OZ8003-CHESTNUT-L | H16: 3 | I16: OZ8007 | J16: 122 | K16: 126 | L16: 130 | M16: 53 | N16: 54 | O16: 55 | P16: 53 | Q16: 54 | R16: 55 | S16: 77 | T16: 78 | U16: 79 | Z16: =UPPER(TRIM(B16))&"|"&UPPER(TRIM(C16))&"|"&UPPER(TRIM(D16))
A17: Ozlana | B17: Ozlana OZ8003 Double Logo Reversible Shearling Coat | C17: HAZELNUT | D17: S | E17: 199.65 | F17: 100 | G17: OZ8003-HAZELNUT-S | H17: 3 | I17: OZ8008 | J17: 118 | K17: 122 | L17: 126 | M17: 55 | N17: 56 | O17: 57 | P17: 53 | Q17: 54 | R17: 55 | S17: 51 | T17: 52 | U17: 53 | Z17: =UPPER(TRIM(B17))&"|"&UPPER(TRIM(C17))&"|"&UPPER(TRIM(D17))
A18: Ozlana | B18: Ozlana OZ8003 Double Logo Reversible Shearling Coat | C18: HAZELNUT | D18: M | E18: 199.65 | F18: 100 | G18: OZ8003-HAZELNUT-M | H18: 3 | I18: OZ8009 | J18: 134 | K18: 138 | L18: 142 | M18: 42 | N18: 43 | O18: 44 | P18: 59 | Q18: 60 | R18: 61 | S18: 56 | T18: 57 | U18: 58 | Z18: =UPPER(TRIM(B18))&"|"&UPPER(TRIM(C18))&"|"&UPPER(TRIM(D18))
A19: Ozlana | B19: Ozlana OZ8003 Double Logo Reversible Shearling Coat | C19: HAZELNUT | D19: L | E19: 199.65 | F19: 100 | G19: OZ8003-HAZELNUT-L | H19: 3 | I19: OZ8010 | J19: 106 | K19: 110 | L19: 114 | M19: 51 | N19: 52 | O19: 53 | P19: 57 | Q19: 58 | R19: 59 | S19: 70 | T19: 71 | U19: 72 | Z19: =UPPER(TRIM(B19))&"|"&UPPER(TRIM(C19))&"|"&UPPER(TRIM(D19))
A20: Ozlana | B20: Ozlana OZ8004 Logo Longline Reversible Shearling Vest | C20: CHESTNUT | D20: S | E20: 154.88 | F20: 100 | G20: OZ8004-CHESTNUT-S | H20: 2 | I20: OZ8011 | J20: 128 | K20: 132 | L20: 136 | M20: 51 | N20: 52 | O20: 53 | P20: 49 | Q20: 50 | R20: 51 | S20: 90 | T20: 91 | U20: 92 | Z20: =UPPER(TRIM(B20))&"|"&UPPER(TRIM(C20))&"|"&UPPER(TRIM(D20))
A21: Ozlana | B21: Ozlana OZ8004 Logo Longline Reversible Shearling Vest | C21: CHESTNUT | D21: M | E21: 154.88 | F21: 100 | G21: OZ8004-CHESTNUT-M | H21: 2 | I21: OZ8012 | J21: 136 | K21: 140 | L21: 144 | M21: 56 | N21: 57 | O21: 58 | P21: 52 | Q21: 53 | R21: 54 | S21: 71 | T21: 72 | U21: 73 | Z21: =UPPER(TRIM(B21))&"|"&UPPER(TRIM(C21))&"|"&UPPER(TRIM(D21))
A22: Ozlana | B22: Ozlana OZ8004 Logo Longline Reversible Shearling Vest | C22: CHESTNUT | D22: L | E22: 154.88 | F22: 100 | G22: OZ8004-CHESTNUT-L | H22: 2 | I22: OZ8013 | J22: 110 | K22: 114 | L22: 118 | M22: 55 | N22: 56 | O22: 57 | P22: 54 | Q22: 55 | R22: 56 | S22: 67 | T22: 68 | U22: 69 | Z22: =UPPER(TRIM(B22))&"|"&UPPER(TRIM(C22))&"|"&UPPER(TRIM(D22))
A23: Ozlana | B23: Ozlana OZ8004 Logo Longline Reversible Shearling Vest | C23: BEIGE | D23: S | E23: 154.88 | F23: 100 | G23: OZ8004-BEIGE-S | H23: 2 | I23: OZ8014 | J23: 104 | K23: 108 | L23: 112 | M23: 41 | N23: 42 | O23: 43 | P23: - | Q23: - | R23: - | S23: 58.5 | T23: 60 | U23: 61.5 | Z23: =UPPER(TRIM(B23))&"|"&UPPER(TRIM(C23))&"|"&UPPER(TRIM(D23))
A24: Ozlana | B24: Ozlana OZ8004 Logo Longline Reversible Shearling Vest | C24: BEIGE | D24: M | E24: 154.88 | F24: 100 | G24: OZ8004-BEIGE-M | H24: 2 | Z24: =UPPER(TRIM(B24))&"|"&UPPER(TRIM(C24))&"|"&UPPER(TRIM(D24))
A25: Ozlana | B25: Ozlana OZ8004 Logo Longline Reversible Shearling Vest | C25: BEIGE | D25: L | E25: 154.88 | F25: 100 | G25: OZ8004-BEIGE-L | H25: 2 | I25: 추천 사이즈 (키 / 몸무게 기준) - 자켓 / 코트 | Z25: =UPPER(TRIM(B25))&"|"&UPPER(TRIM(C25))&"|"&UPPER(TRIM(D25))
A26: Ozlana | B26: Ozlana OZ8004 Logo Longline Reversible Shearling Vest | C26: TAUPE | D26: S | E26: 154.88 | F26: 100 | G26: OZ8004-TAUPE-S | H26: 2 | I26: CM \ KG | J26: 40KG | K26: 45KG | L26: 50KG | M26: 55KG | N26: 60KG | O26: 65KG | P26: 70KG | Q26: 75KG | R26: 80KG | S26: 85KG | Z26: =UPPER(TRIM(B26))&"|"&UPPER(TRIM(C26))&"|"&UPPER(TRIM(D26))
A27: Ozlana | B27: Ozlana OZ8004 Logo Longline Reversible Shearling Vest | C27: TAUPE | D27: M | E27: 154.88 | F27: 100 | G27: OZ8004-TAUPE-M | H27: 2 | I27: 155CM | J27: S | K27: S | L27: S | M27: M | N27: M | O27: M | P27: L | Q27: L | R27: L | S27: L | Z27: =UPPER(TRIM(B27))&"|"&UPPER(TRIM(C27))&"|"&UPPER(TRIM(D27))
A28: Ozlana | B28: Ozlana OZ8004 Logo Longline Reversible Shearling Vest | C28: TAUPE | D28: L | E28: 154.88 | F28: 100 | G28: OZ8004-TAUPE-L | H28: 2 | I28: 160CM | J28: S | K28: S | L28: S | M28: M | N28: M | O28: M | P28: L | Q28: L | R28: L | S28: L | Z28: =UPPER(TRIM(B28))&"|"&UPPER(TRIM(C28))&"|"&UPPER(TRIM(D28))
A29: Ozlana | B29: Ozlana OZ8005 Double Logo Short Reversible Shearling Jacket | C29: CHESTNUT | D29: S | E29: 193.6 | F29: 100 | G29: OZ8005-CHESTNUT-S | H29: 3 | I29: 165CM | J29: S | K29: S | L29: S | M29: S | N29: M | O29: M | P29: L | Q29: L | R29: L | S29: L | Z29: =UPPER(TRIM(B29))&"|"&UPPER(TRIM(C29))&"|"&UPPER(TRIM(D29))
A30: Ozlana | B30: Ozlana OZ8005 Double Logo Short Reversible Shearling Jacket | C30: CHESTNUT | D30: M | E30: 193.6 | F30: 100 | G30: OZ8005-CHESTNUT-M | H30: 3 | I30: 170CM | J30: S | K30: S | L30: S | M30: S | N30: M | O30: M | P30: M | Q30: L | R30: L | S30: L | Z30: =UPPER(TRIM(B30))&"|"&UPPER(TRIM(C30))&"|"&UPPER(TRIM(D30))
A31: Ozlana | B31: Ozlana OZ8005 Double Logo Short Reversible Shearling Jacket | C31: CHESTNUT | D31: L | E31: 193.6 | F31: 100 | G31: OZ8005-CHESTNUT-L | H31: 3 | I31: 175CM | J31: S | K31: S | L31: S | M31: S | N31: M | O31: M | P31: M | Q31: L | R31: L | S31: L | Z31: =UPPER(TRIM(B31))&"|"&UPPER(TRIM(C31))&"|"&UPPER(TRIM(D31))
A32: Ozlana | B32: Ozlana OZ8005 Double Logo Short Reversible Shearling Jacket | C32: CHOCOLATE | D32: S | E32: 193.6 | F32: 100 | G32: OZ8005-CHOCOLATE-S | H32: 3 | Z32: =UPPER(TRIM(B32))&"|"&UPPER(TRIM(C32))&"|"&UPPER(TRIM(D32))
A33: Ozlana | B33: Ozlana OZ8005 Double Logo Short Reversible Shearling Jacket | C33: CHOCOLATE | D33: M | E33: 193.6 | F33: 100 | G33: OZ8005-CHOCOLATE-M | H33: 3 | I33: 추천 사이즈 (키 / 몸무게 기준) - 조끼 (OZ8004, OZ8014) | Z33: =UPPER(TRIM(B33))&"|"&UPPER(TRIM(C33))&"|"&UPPER(TRIM(D33))
A34: Ozlana | B34: Ozlana OZ8005 Double Logo Short Reversible Shearling Jacket | C34: CHOCOLATE | D34: L | E34: 193.6 | F34: 100 | G34: OZ8005-CHOCOLATE-L | H34: 3 | I34: CM \ KG | J34: 40KG | K34: 45KG | L34: 50KG | M34: 55KG | N34: 60KG | O34: 65KG | P34: 70KG | Q34: 75KG | R34: 80KG | S34: 85KG | Z34: =UPPER(TRIM(B34))&"|"&UPPER(TRIM(C34))&"|"&UPPER(TRIM(D34))
A35: Ozlana | B35: Ozlana OZ8006 Double Logo Stand-Collar Reversible Shearling Coat | C35: CHESTNUT | D35: S | E35: 193.6 | F35: 100 | G35: OZ8006-CHESTNUT-S | H35: 3 | I35: 155CM | J35: S | K35: S | L35: S | M35: M | N35: M | O35: M | P35: L | Q35: L | R35: L | S35: L | Z35: =UPPER(TRIM(B35))&"|"&UPPER(TRIM(C35))&"|"&UPPER(TRIM(D35))
A36: Ozlana | B36: Ozlana OZ8006 Double Logo Stand-Collar Reversible Shearling Coat | C36: CHESTNUT | D36: M | E36: 193.6 | F36: 100 | G36: OZ8006-CHESTNUT-M | H36: 3 | I36: 160CM | J36: S | K36: S | L36: S | M36: M | N36: M | O36: M | P36: L | Q36: L | R36: L | S36: L | Z36: =UPPER(TRIM(B36))&"|"&UPPER(TRIM(C36))&"|"&UPPER(TRIM(D36))
A37: Ozlana | B37: Ozlana OZ8006 Double Logo Stand-Collar Reversible Shearling Coat | C37: CHESTNUT | D37: L | E37: 193.6 | F37: 100 | G37: OZ8006-CHESTNUT-L | H37: 3 | I37: 165CM | J37: S | K37: S | L37: S | M37: M | N37: M | O37: M | P37: L | Q37: L | R37: L | S37: L | Z37: =UPPER(TRIM(B37))&"|"&UPPER(TRIM(C37))&"|"&UPPER(TRIM(D37))
A38: Ozlana | B38: Ozlana OZ8006 Double Logo Stand-Collar Reversible Shearling Coat | C38: CHOCOLATE | D38: S | E38: 193.6 | F38: 100 | G38: OZ8006-CHOCOLATE-S | H38: 3 | I38: 170CM | J38: S | K38: S | L38: S | M38: M | N38: M | O38: M | P38: L | Q38: L | R38: L | S38: L | Z38: =UPPER(TRIM(B38))&"|"&UPPER(TRIM(C38))&"|"&UPPER(TRIM(D38))
A39: Ozlana | B39: Ozlana OZ8006 Double Logo Stand-Collar Reversible Shearling Coat | C39: CHOCOLATE | D39: M | E39: 193.6 | F39: 100 | G39: OZ8006-CHOCOLATE-M | H39: 3 | I39: 175CM | J39: S | K39: S | L39: S | M39: S | N39: M | O39: M | P39: L | Q39: L | R39: L | S39: L | Z39: =UPPER(TRIM(B39))&"|"&UPPER(TRIM(C39))&"|"&UPPER(TRIM(D39))
A40: Ozlana | B40: Ozlana OZ8006 Double Logo Stand-Collar Reversible Shearling Coat | C40: CHOCOLATE | D40: L | E40: 193.6 | F40: 100 | G40: OZ8006-CHOCOLATE-L | H40: 3 | Z40: =UPPER(TRIM(B40))&"|"&UPPER(TRIM(C40))&"|"&UPPER(TRIM(D40))
...

Sheet OZWEAR
A1: 브랜드 | B1: 상품명 | C1: 색상 | D1: 사이즈 | E1: 가격(AUD) | F1: 재고 | G1: SKU | H1: 무게(kg) | I1: MEN'S SHEEPSKIN BOOTS SIZE CHART | Z1: 조회키
A2: OZWEAR UGG | B2: KIDS CLASSIC UGG BUTTON BOOTS (WATER RESISTANT) (OB022 II) | C2: CHESTNUT | D2: 5/6 | E2: 50.82 | F2: 43 | G2: 9341517099493 | H2: 1 | I2: AUSTRALIAN MENS | J2: 6M | K2: 7M | L2: 8M | M2: 9M | N2: 10M | O2: 11M | P2: 12M | Z2: =UPPER(TRIM(B2))&"|"&UPPER(TRIM(C2))&"|"&UPPER(TRIM(D2))
A3: OZWEAR UGG | B3: KIDS CLASSIC UGG BUTTON BOOTS (WATER RESISTANT) (OB022 II) | C3: CHESTNUT | D3: 7/8 | E3: 50.82 | F3: 63 | G3: 9341517099509 | H3: 1 | I3: CHINESE | J3: 248 | K3: 256 | L3: 264 | M3: 273 | N3: 281 | O3: 289 | P3: 298 | Z3: =UPPER(TRIM(B3))&"|"&UPPER(TRIM(C3))&"|"&UPPER(TRIM(D3))
A4: OZWEAR UGG | B4: KIDS CLASSIC UGG BUTTON BOOTS (WATER RESISTANT) (OB022 II) | C4: CHESTNUT | D4: 9/10 | E4: 50.82 | F4: 62 | G4: 9341517099516 | H4: 1 | I4: EUROPEAN | J4: 39 | K4: 40 | L4: 41 | M4: 42 | N4: 43 | O4: 44 | P4: 45 | Z4: =UPPER(TRIM(B4))&"|"&UPPER(TRIM(C4))&"|"&UPPER(TRIM(D4))
A5: OZWEAR UGG | B5: KIDS CLASSIC UGG BUTTON BOOTS (WATER RESISTANT) (OB022 II) | C5: CHESTNUT | D5: 11/12 | E5: 55.9 | F5: 53 | G5: 9341517085458 | H5: 1 | I5: UK MENS | J5: 6 | K5: 7 | L5: 8 | M5: 9 | N5: 10 | O5: 11 | P5: 12 | Z5: =UPPER(TRIM(B5))&"|"&UPPER(TRIM(C5))&"|"&UPPER(TRIM(D5))
A6: OZWEAR UGG | B6: KIDS CLASSIC UGG BUTTON BOOTS (WATER RESISTANT) (OB022 II) | C6: CHESTNUT | D6: 13/1 | E6: 50.82 | F6: 70 | G6: 9341517085465 | H6: 1 | I6: AMERICAN MENS | J6: 7/8 | K6: 8/9 | L6: 9/10 | M6: 10/11 | N6: 11/12 | O6: 12/13 | P6: 13/14 | Z6: =UPPER(TRIM(B6))&"|"&UPPER(TRIM(C6))&"|"&UPPER(TRIM(D6))
A7: OZWEAR UGG | B7: KIDS CLASSIC UGG BUTTON BOOTS (WATER RESISTANT) (OB022 II) | C7: CHESTNUT | D7: 2/3 | E7: 50.82 | F7: 53 | G7: 9341517085472 | H7: 1 | I7: JAPANESE | J7: 25 | K7: 26 | L7: 27 | M7: 28 | N7: 29 | O7: 30 | P7: 31 | Z7: =UPPER(TRIM(B7))&"|"&UPPER(TRIM(C7))&"|"&UPPER(TRIM(D7))
A8: OZWEAR UGG | B8: KIDS CLASSIC UGG BUTTON BOOTS (WATER RESISTANT) (OB022 II) | C8: ROSE | D8: 5/6 | E8: 50.82 | F8: 0 | G8: 9341517085489 | H8: 1 | I8: KOREAN | J8: 245 | K8: 255 | L8: 265 | M8: 275 | N8: 285 | O8: 295 | P8: 305 | Z8: =UPPER(TRIM(B8))&"|"&UPPER(TRIM(C8))&"|"&UPPER(TRIM(D8))
A9: OZWEAR UGG | B9: KIDS CLASSIC UGG BUTTON BOOTS (WATER RESISTANT) (OB022 II) | C9: ROSE | D9: 7/8 | E9: 50.82 | F9: 0 | G9: 9341517085496 | H9: 1 | I9: FOOT LENGTH: CM | J9: 24.8 | K9: 25.6 | L9: 26.4 | M9: 27.3 | N9: 28.1 | O9: 28.9 | P9: 29.8 | Z9: =UPPER(TRIM(B9))&"|"&UPPER(TRIM(C9))&"|"&UPPER(TRIM(D9))
A10: OZWEAR UGG | B10: KIDS CLASSIC UGG BUTTON BOOTS (WATER RESISTANT) (OB022 II) | C10: ROSE | D10: 9/10 | E10: 50.82 | F10: 0 | G10: 9341517085083 | H10: 1 | Z10: =UPPER(TRIM(B10))&"|"&UPPER(TRIM(C10))&"|"&UPPER(TRIM(D10))
A11: OZWEAR UGG | B11: KIDS CLASSIC UGG BUTTON BOOTS (WATER RESISTANT) (OB022 II) | C11: ROSE | D11: 11/12 | E11: 50.82 | F11: 0 | G11: 9341517085090 | H11: 1 | I11: WOMEN'S SHEEPSKIN SHOES & SLIPPERS/BOOTS SIZE CHART | Z11: =UPPER(TRIM(B11))&"|"&UPPER(TRIM(C11))&"|"&UPPER(TRIM(D11))
A12: OZWEAR UGG | B12: KIDS CLASSIC UGG BUTTON BOOTS (WATER RESISTANT) (OB022 II) | C12: ROSE | D12: 13/1 | E12: 50.82 | F12: 0 | G12: 9341517085106 | H12: 1 | I12: AUSTRALIAN LADIES | J12: 5L | K12: 6L | L12: 7L | M12: 8L | N12: 9L | O12: 10L | P12: 11L | Z12: =UPPER(TRIM(B12))&"|"&UPPER(TRIM(C12))&"|"&UPPER(TRIM(D12))
A13: OZWEAR UGG | B13: KIDS CLASSIC UGG BUTTON BOOTS (WATER RESISTANT) (OB022 II) | C13: ROSE | D13: 2/3 | E13: 50.82 | F13: 0 | G13: 9341517085113 | H13: 1 | I13: EUROPEAN | J13: 35 | K13: 36 | L13: 37 | M13: 38 | N13: 39 | O13: 40 | P13: 41 | Z13: =UPPER(TRIM(B13))&"|"&UPPER(TRIM(C13))&"|"&UPPER(TRIM(D13))
A14: OZWEAR UGG | B14: KIDS CLASSIC UGG BUTTON BOOTS (WATER RESISTANT) (OB022 II) | C14: OLIVE | D14: 5/6 | E14: 50.82 | F14: 27 | G14: 9341517190213 | H14: 1 | I14: UK LADIES | J14: 3 | K14: 4 | L14: 5 | M14: 6 | N14: 7 | O14: 8 | P14: 9 | Z14: =UPPER(TRIM(B14))&"|"&UPPER(TRIM(C14))&"|"&UPPER(TRIM(D14))
A15: OZWEAR UGG | B15: KIDS CLASSIC UGG BUTTON BOOTS (WATER RESISTANT) (OB022 II) | C15: OLIVE | D15: 7/8 | E15: 50.82 | F15: 28 | G15: 9341517190220 | H15: 1 | I15: AMERICAN LADIES | J15: 4/5 | K15: 5/6 | L15: 6/7 | M15: 7/8 | N15: 8/9 | O15: 9/10 | P15: 10/11 | Z15: =UPPER(TRIM(B15))&"|"&UPPER(TRIM(C15))&"|"&UPPER(TRIM(D15))
A16: OZWEAR UGG | B16: KIDS CLASSIC UGG BUTTON BOOTS (WATER RESISTANT) (OB022 II) | C16: OLIVE | D16: 9/10 | E16: 50.82 | F16: 39 | G16: 9341517190237 | H16: 1 | I16: JAPANESE | J16: 22 | K16: 23 | L16: 24 | M16: 25 | N16: 26 | O16: 27 | P16: 28 | Z16: =UPPER(TRIM(B16))&"|"&UPPER(TRIM(C16))&"|"&UPPER(TRIM(D16))
A17: OZWEAR UGG | B17: KIDS CLASSIC UGG BUTTON BOOTS (WATER RESISTANT) (OB022 II) | C17: OLIVE | D17: 11/12 | E17: 50.82 | F17: 66 | G17: 9341517190183 | H17: 1 | I17: KOREAN | J17: 225 | K17: 230 | L17: 235 | M17: 240 | N17: 245 | O17: 255 | P17: 265 | Z17: =UPPER(TRIM(B17))&"|"&UPPER(TRIM(C17))&"|"&UPPER(TRIM(D17))
A18: OZWEAR UGG | B18: KIDS CLASSIC UGG BUTTON BOOTS (WATER RESISTANT) (OB022 II) | C18: OLIVE | D18: 13/1 | E18: 50.82 | F18: 50 | G18: 9341517190190 | H18: 1 | I18: FOOT LENGTH: CM | J18: 22 | K18: 23 | L18: 23.5 | M18: 24.5 | N18: 25 | O18: 26 | P18: 27 | Z18: =UPPER(TRIM(B18))&"|"&UPPER(TRIM(C18))&"|"&UPPER(TRIM(D18))
A19: OZWEAR UGG | B19: KIDS CLASSIC UGG BUTTON BOOTS (WATER RESISTANT) (OB022 II) | C19: OLIVE | D19: 2/3 | E19: 50.82 | F19: 28 | G19: 9341517190206 | H19: 1 | Z19: =UPPER(TRIM(B19))&"|"&UPPER(TRIM(C19))&"|"&UPPER(TRIM(D19))
A20: OZWEAR UGG | B20: KIDS CLASSIC UGG BUTTON BOOTS (WATER RESISTANT) (OB022 II) | C20: PALE MAUVE | D20: 5/6 | E20: 50.82 | F20: 56 | G20: 9341517190275 | H20: 1 | I20: COW SUEDE CLASSIC BOOTS / UNISEX STYLE SIZE CHART | Z20: =UPPER(TRIM(B20))&"|"&UPPER(TRIM(C20))&"|"&UPPER(TRIM(D20))
A21: OZWEAR UGG | B21: KIDS CLASSIC UGG BUTTON BOOTS (WATER RESISTANT) (OB022 II) | C21: PALE MAUVE | D21: 7/8 | E21: 50.82 | F21: 34 | G21: 9341517190282 | H21: 1 | I21: AUSTRALIAN M/L | J21: 2M/4L | K21: 3M/5L | L21: 4M/6L | M21: 5M/7L | N21: 6M/8L | O21: 7M/9L | P21: 8M/10L | Q21: 9M/11L | R21: 10M/12L | S21: 11M/13L | T21: 12M/14L | U21: 13M/15L | V21: 14M/16L | Z21: =UPPER(TRIM(B21))&"|"&UPPER(TRIM(C21))&"|"&UPPER(TRIM(D21))
A22: OZWEAR UGG | B22: KIDS CLASSIC UGG BUTTON BOOTS (WATER RESISTANT) (OB022 II) | C22: PALE MAUVE | D22: 9/10 | E22: 50.82 | F22: 9 | G22: 9341517190299 | H22: 1 | I22: EUROPEAN | J22: 35 | K22: 36 | L22: 37 | M22: 38 | N22: 39 | O22: 40 | P22: 41 | Q22: 42 | R22: 43 | S22: 44 | T22: 45 | U22: 46 | V22: 47 | Z22: =UPPER(TRIM(B22))&"|"&UPPER(TRIM(C22))&"|"&UPPER(TRIM(D22))
A23: OZWEAR UGG | B23: KIDS CLASSIC UGG BUTTON BOOTS (WATER RESISTANT) (OB022 II) | C23: PALE MAUVE | D23: 11/12 | E23: 50.82 | F23: 18 | G23: 9341517190244 | H23: 1 | I23: UK MENS&LADIES | J23: 3 | K23: 4 | L23: 5 | M23: 6 | N23: 7 | O23: 8 | P23: 9 | Q23: 10 | R23: 11 | S23: 12 | T23: 13 | U23: 14 | V23: 15 | Z23: =UPPER(TRIM(B23))&"|"&UPPER(TRIM(C23))&"|"&UPPER(TRIM(D23))
A24: OZWEAR UGG | B24: KIDS CLASSIC UGG BUTTON BOOTS (WATER RESISTANT) (OB022 II) | C24: PALE MAUVE | D24: 13/1 | E24: 50.82 | F24: 14 | G24: 9341517190251 | H24: 1 | I24: AMERICAN M/L | J24: 4/5 | K24: 5/6 | L24: 6/7 | M24: 7/8 | N24: 8/9 | O24: 9/10 | P24: 10/11 | Q24: 11/12 | R24: 12/13 | S24: 13/14 | T24: 14/15 | U24: 15/16 | V24: 16/17 | Z24: =UPPER(TRIM(B24))&"|"&UPPER(TRIM(C24))&"|"&UPPER(TRIM(D24))
A25: OZWEAR UGG | B25: KIDS CLASSIC UGG BUTTON BOOTS (WATER RESISTANT) (OB022 II) | C25: PALE MAUVE | D25: 2/3 | E25: 50.82 | F25: 33 | G25: 9341517190268 | H25: 1 | I25: JAPANESE | J25: 22 | K25: 23 | L25: 24 | M25: 25 | N25: 26 | O25: 27 | P25: 28 | Q25: 29 | R25: 30 | S25: 31 | T25: 33 | U25: 34 | V25: 35 | Z25: =UPPER(TRIM(B25))&"|"&UPPER(TRIM(C25))&"|"&UPPER(TRIM(D25))
A26: OZWEAR UGG | B26: KIDS CLASSIC UGG LONG BOOTS (WATER RESISTANT) (OB007 II) | C26: CHARCOAL | D26: 5/6 | E26: 49.61 | F26: 0 | G26: 9341517083331 | H26: 2 | I26: FOOT LENGTH: CM | J26: 22.3 | K26: 23.1 | L26: 23.9 | M26: 24.7 | N26: 25.5 | O26: 26.3 | P26: 27.1 | Q26: 27.9 | R26: 28.7 | S26: 29.5 | T26: 30.5 | U26: 31.5 | V26: 32.5 | Z26: =UPPER(TRIM(B26))&"|"&UPPER(TRIM(C26))&"|"&UPPER(TRIM(D26))
A27: OZWEAR UGG | B27: KIDS CLASSIC UGG LONG BOOTS (WATER RESISTANT) (OB007 II) | C27: CHARCOAL | D27: 7/8 | E27: 49.61 | F27: 0 | G27: 9341517083348 | H27: 2 | Z27: =UPPER(TRIM(B27))&"|"&UPPER(TRIM(C27))&"|"&UPPER(TRIM(D27))
A28: OZWEAR UGG | B28: KIDS CLASSIC UGG LONG BOOTS (WATER RESISTANT) (OB007 II) | C28: CHARCOAL | D28: 9/10 | E28: 49.61 | F28: 0 | G28: 9341517083355 | H28: 2 | I28: SLIPPER SIZE (SHEEPSKIN) | Z28: =UPPER(TRIM(B28))&"|"&UPPER(TRIM(C28))&"|"&UPPER(TRIM(D28))
A29: OZWEAR UGG | B29: KIDS CLASSIC UGG LONG BOOTS (WATER RESISTANT) (OB007 II) | C29: CHARCOAL | D29: 11/12 | E29: 49.61 | F29: 0 | G29: 9341517083362 | H29: 2 | J29: S | K29: M | L29: L | M29: XL | Z29: =UPPER(TRIM(B29))&"|"&UPPER(TRIM(C29))&"|"&UPPER(TRIM(D29))
A30: OZWEAR UGG | B30: KIDS CLASSIC UGG LONG BOOTS (WATER RESISTANT) (OB007 II) | C30: CHARCOAL | D30: 13/1 | E30: 49.61 | F30: 0 | G30: 9341517083379 | H30: 2 | I30: WOMEN | J30: 35/36 | K30: 37/38 | L30: 39/40 | M30: 41/42 | Z30: =UPPER(TRIM(B30))&"|"&UPPER(TRIM(C30))&"|"&UPPER(TRIM(D30))
A31: OZWEAR UGG | B31: KIDS CLASSIC UGG LONG BOOTS (WATER RESISTANT) (OB007 II) | C31: CHARCOAL | D31: 2/3 | E31: 49.61 | F31: 0 | G31: 9341517083386 | H31: 2 | I31: MEN | J31: 39/40 | K31: 41/42 | L31: 43/44 | M31: 45/46 | Z31: =UPPER(TRIM(B31))&"|"&UPPER(TRIM(C31))&"|"&UPPER(TRIM(D31))
A32: OZWEAR UGG | B32: KIDS CLASSIC UGG LONG BOOTS (WATER RESISTANT) (OB007 II) | C32: CHESTNUT | D32: 5/6 | E32: 49.61 | F32: 167 | G32: 9341517083218 | H32: 2 | Z32: =UPPER(TRIM(B32))&"|"&UPPER(TRIM(C32))&"|"&UPPER(TRIM(D32))
A33: OZWEAR UGG | B33: KIDS CLASSIC UGG LONG BOOTS (WATER RESISTANT) (OB007 II) | C33: CHESTNUT | D33: 7/8 | E33: 49.61 | F33: 181 | G33: 9341517083225 | H33: 2 | I33: BABY BOOTS SIZE CHART | Z33: =UPPER(TRIM(B33))&"|"&UPPER(TRIM(C33))&"|"&UPPER(TRIM(D33))
A34: OZWEAR UGG | B34: KIDS CLASSIC UGG LONG BOOTS (WATER RESISTANT) (OB007 II) | C34: CHESTNUT | D34: 9/10 | E34: 49.61 | F34: 149 | G34: 9341517083232 | H34: 2 | I34: BABY SIZES | J34: S | K34: M | L34: L | M34: XL | Z34: =UPPER(TRIM(B34))&"|"&UPPER(TRIM(C34))&"|"&UPPER(TRIM(D34))
A35: OZWEAR UGG | B35: KIDS CLASSIC UGG LONG BOOTS (WATER RESISTANT) (OB007 II) | C35: CHESTNUT | D35: 11/12 | E35: 49.61 | F35: 107 | G35: 9341517083249 | H35: 2 | I35: BABY'S AGES | J35: 0-6 MONTH | K35: 7-12 MONTH | L35: 1-2 YEAR | M35: 2-3 YEAR | Z35: =UPPER(TRIM(B35))&"|"&UPPER(TRIM(C35))&"|"&UPPER(TRIM(D35))
A36: OZWEAR UGG | B36: KIDS CLASSIC UGG LONG BOOTS (WATER RESISTANT) (OB007 II) | C36: CHESTNUT | D36: 13/1 | E36: 49.61 | F36: 101 | G36: 9341517083256 | H36: 2 | I36: FOOT LENGTH: CM | J36: Up to 10cm | K36: Up to 12cm | L36: Up to 13cm | M36: Up to 14cm | Z36: =UPPER(TRIM(B36))&"|"&UPPER(TRIM(C36))&"|"&UPPER(TRIM(D36))
A37: OZWEAR UGG | B37: KIDS CLASSIC UGG LONG BOOTS (WATER RESISTANT) (OB007 II) | C37: CHESTNUT | D37: 2/3 | E37: 49.61 | F37: 134 | G37: 9341517083263 | H37: 2 | Z37: =UPPER(TRIM(B37))&"|"&UPPER(TRIM(C37))&"|"&UPPER(TRIM(D37))
A38: OZWEAR UGG | B38: KIDS CLASSIC UGG LONG BOOTS (WATER RESISTANT) (OB007 II) | C38: HIBISCUS | D38: 5/6 | E38: 49.61 | F38: 0 | G38: 9341517083270 | H38: 2 | I38: CHILDREN SIZE CHART | Z38: =UPPER(TRIM(B38))&"|"&UPPER(TRIM(C38))&"|"&UPPER(TRIM(D38))
A39: OZWEAR UGG | B39: KIDS CLASSIC UGG LONG BOOTS (WATER RESISTANT) (OB007 II) | C39: HIBISCUS | D39: 7/8 | E39: 49.61 | F39: 0 | G39: 9341517083287 | H39: 2 | I39: AUSTRALIAN | J39: 5/6 | K39: 7/8 | L39: 9/10 | M39: 11/12 | N39: 13/1 | O39: 2/3 | Z39: =UPPER(TRIM(B39))&"|"&UPPER(TRIM(C39))&"|"&UPPER(TRIM(D39))
A40: OZWEAR UGG | B40: KIDS CLASSIC UGG LONG BOOTS (WATER RESISTANT) (OB007 II) | C40: HIBISCUS | D40: 9/10 | E40: 49.61 | F40: 0 | G40: 9341517083294 | H40: 2 | I40: CHINESE/KOREAN | J40: 145 | K40: 165 | L40: 180 | M40: 190 | N40: 200 | O40: 210 | Z40: =UPPER(TRIM(B40))&"|"&UPPER(TRIM(C40))&"|"&UPPER(TRIM(D40))
...
